import React from 'react';
import { render, screen, fireEvent } from '@testing-library/react';
import { vi } from 'vitest';
import ErrorBoundary from '../ErrorBoundary';

// Mock component that throws an error
const ThrowError = ({ shouldThrow }) => {
  if (shouldThrow) {
    throw new Error('Test error');
  }
  return <div>No error</div>;
};

describe('ErrorBoundary', () => {
  // Suppress console.error for these tests
  const originalError = console.error;
  beforeAll(() => {
    console.error = vi.fn();
  });
  
  afterAll(() => {
    console.error = originalError;
  });

  it('renders children when there is no error', () => {
    render(
      <ErrorBoundary>
        <ThrowError shouldThrow={false} />
      </ErrorBoundary>
    );
    
    expect(screen.getByText('No error')).toBeInTheDocument();
  });

  it('renders error UI when there is an error', () => {
    render(
      <ErrorBoundary>
        <ThrowError shouldThrow={true} />
      </ErrorBoundary>
    );
    
    expect(screen.getByText('Oops! Something went wrong')).toBeInTheDocument();
    expect(screen.getByText('We encountered an unexpected error. Don\'t worry, your data is safe.')).toBeInTheDocument();
  });

  it('shows retry and go home buttons', () => {
    render(
      <ErrorBoundary>
        <ThrowError shouldThrow={true} />
      </ErrorBoundary>
    );
    
    expect(screen.getByText('Try Again')).toBeInTheDocument();
    expect(screen.getByText('Go to Dashboard')).toBeInTheDocument();
  });

  it('calls onError callback when error occurs', () => {
    const onError = vi.fn();
    
    render(
      <ErrorBoundary onError={onError}>
        <ThrowError shouldThrow={true} />
      </ErrorBoundary>
    );
    
    expect(onError).toHaveBeenCalled();
  });

  it('renders custom fallback when provided', () => {
    const customFallback = (error, retry) => (
      <div>
        <p>Custom error: {error.message}</p>
        <button onClick={retry}>Custom Retry</button>
      </div>
    );
    
    render(
      <ErrorBoundary fallback={customFallback}>
        <ThrowError shouldThrow={true} />
      </ErrorBoundary>
    );
    
    expect(screen.getByText('Custom error: Test error')).toBeInTheDocument();
    expect(screen.getByText('Custom Retry')).toBeInTheDocument();
  });

  it('resets error state when retry is clicked', () => {
    const { rerender } = render(
      <ErrorBoundary>
        <ThrowError shouldThrow={true} />
      </ErrorBoundary>
    );
    
    expect(screen.getByText('Oops! Something went wrong')).toBeInTheDocument();
    
    fireEvent.click(screen.getByText('Try Again'));
    
    rerender(
      <ErrorBoundary>
        <ThrowError shouldThrow={false} />
      </ErrorBoundary>
    );
    
    expect(screen.getByText('No error')).toBeInTheDocument();
  });

  it('shows error details in development mode', () => {
    const originalEnv = process.env.NODE_ENV;
    process.env.NODE_ENV = 'development';
    
    render(
      <ErrorBoundary>
        <ThrowError shouldThrow={true} />
      </ErrorBoundary>
    );
    
    expect(screen.getByText('Error Details:')).toBeInTheDocument();
    expect(screen.getByText(/Test error/)).toBeInTheDocument();
    
    process.env.NODE_ENV = originalEnv;
  });
});